<?xml version="1.0" encoding="UTF-8"?>
<robot name="denso_cobotta" xmlns:xacro="http://www.ros.org/wiki/xacro">
	<xacro:arg name="gripper_type" default="taiyo"/>
	<xacro:property name="gripper_type" value="$(arg gripper_type)" />
	<xacro:property name="scale_value" value="100.0"/>

	<link name="world"/>
	<joint name="joint_w" type="fixed">
		<parent link="world"/>
		<child link="base_link"/>
		<origin rpy="0.000000 0.000000 1.5707" xyz="17.00 -6.0 18.16" />
	</joint>
	
	<link name="base_link">
		<visual>
			<origin rpy="0 0 0" xyz="0 0 0"/>
			<geometry>
				<mesh filename="package://denso_cobotta_description/meshes/visual/robot/base_link.dae" scale="${scale_value} ${scale_value} ${scale_value}"/>
			</geometry>
		</visual>
		<collision>
			<origin rpy="0 0 0" xyz="0 0 0"/>
			<geometry>
				<mesh filename="package://denso_cobotta_description/meshes/collision/robot/base_link.dae" scale="${scale_value} ${scale_value} ${scale_value}"/>
			</geometry>
		</collision>
	</link>

	<link name="link_1">
		<visual>
			<origin rpy="0 0 0" xyz="0 0 0"/>
			<geometry>
				<mesh filename="package://denso_cobotta_description/meshes/visual/robot/link_1.dae" scale="${scale_value} ${scale_value} ${scale_value}"/>
			</geometry>
		</visual>
		<collision>
			<origin rpy="0 0 0" xyz="0 0 0"/>
			<geometry>
				<mesh filename="package://denso_cobotta_description/meshes/collision/robot/link_1.dae" scale="${scale_value} ${scale_value} ${scale_value}"/>
			</geometry>
		</collision>
	</link>

	<joint name="joint_1" type="revolute">
		<parent link="base_link"/>
		<child link="link_1" />
		<origin rpy="0.000000 0.000000 0.000000" xyz="0.000000 0.000000 0.000000" />
		<axis xyz="-0.000000 -0.000000 1.000000" />
		<limit effort="${scale_value * 10000}" lower="-2.617994" upper="2.617994" velocity="${scale_value * 0.403171057210690}" />
	</joint>

	<link name="link_2">
		<visual>
			<origin rpy="0 0 0" xyz="0 0 0"/>
			<geometry>
				<mesh filename="package://denso_cobotta_description/meshes/visual/robot/link_2.dae" scale="${scale_value} ${scale_value} ${scale_value}"/>
			</geometry>
		</visual>
		<collision>
			<origin rpy="0 0 0" xyz="0 0 0"/>
			<geometry>
				<mesh filename="package://denso_cobotta_description/meshes/collision/robot/link_2.dae" scale="${scale_value} ${scale_value} ${scale_value}"/>
			</geometry>
		</collision>
	</link>

	<joint name="joint_2" type="revolute">
		<parent link="link_1"/>
		<child link="link_2"/>
		<origin rpy="0.000000 0.000000 0.000000" xyz="0.000000 0.000000 ${scale_value * 0.180000}" />
		<axis xyz="-0.000000 1.000000 -0.000000" />
		<limit effort="${scale_value * 10000}" lower="-1.047198" upper="1.745329" velocity="${scale_value * 0.392175482923126}" />
	</joint>
	<link name="link_3">
		<visual>
			<origin rpy="0 0 0" xyz="0 0 0"/>
			<geometry>
				<mesh filename="package://denso_cobotta_description/meshes/visual/robot/link_3.dae" scale="${scale_value} ${scale_value} ${scale_value}"/>
			</geometry>
		</visual>
		<collision>
			<origin rpy="0 0 0" xyz="0 0 0"/>
			<geometry>
				<mesh filename="package://denso_cobotta_description/meshes/collision/robot/link_3.dae" scale="${scale_value} ${scale_value} ${scale_value}"/>
			</geometry>
		</collision>
	</link>

	<joint name="joint_3" type="revolute">
		<parent link="link_2"/>
		<child link="link_3"/>
		<origin rpy="0.000000 0.000000 0.000000" xyz="0.000000 0.000000 ${scale_value * 0.165000}" />
		<axis xyz="-0.000000 1.000000 -0.000000" />
		<limit effort="${scale_value * 10000}" lower="0.3141593" upper="2.443461" velocity="${scale_value * 0.725707902979242}" />
	</joint>

	<link name="link_4">
		<visual>
			<origin rpy="0 0 0" xyz="0 0 0"/>
			<geometry>
				<mesh filename="package://denso_cobotta_description/meshes/visual/robot/link_4.dae" scale="${scale_value} ${scale_value} ${scale_value}"/>
			</geometry>
		</visual>
		<collision>
			<origin rpy="0 0 0" xyz="0 0 0"/>
			<geometry>
				<mesh filename="package://denso_cobotta_description/meshes/collision/robot/link_4.dae" scale="${scale_value} ${scale_value} ${scale_value}"/>
			</geometry>
		</collision>
	</link>

	<joint name="joint_4" type="revolute">
		<parent link="link_3"/>
		<child link="link_4"/>
		<origin rpy="0.000000 0.000000 0.000000" xyz="${scale_value * (-0.012000)} ${scale_value * 0.020000} ${scale_value * 0.088000}" />
		<axis xyz="-0.000000 -0.000000 1.000000" />
		<limit effort="${scale_value * 10000}" lower="-2.96706" upper="2.96706" velocity="${scale_value * 0.739146938219599}" />
	</joint>

	<link name="link_5">
		<visual>
			<origin rpy="0 0 0" xyz="0 0 0"/>
			<geometry>
				<mesh filename="package://denso_cobotta_description/meshes/visual/robot/link_5.dae" scale="${scale_value} ${scale_value} ${scale_value}"/>
			</geometry>
		</visual>
		<collision>
			<origin rpy="0 0 0" xyz="0 0 0"/>
			<geometry>
				<mesh filename="package://denso_cobotta_description/meshes/collision/robot/link_5.dae" scale="${scale_value} ${scale_value} ${scale_value}"/>
			</geometry>
		</collision>
	</link>

	<joint name="joint_5" type="revolute">
		<parent link="link_4"/>
		<child link="link_5"/>
		<origin rpy="0.000000 0.000000 0.000000" xyz="0.000000 ${scale_value * (-0.020000)} ${scale_value * 0.089500}" />
		<axis xyz="-0.000000 1.000000 -0.000000" />
		<limit effort="${scale_value * 10000}" lower="-1.658063" upper="2.356194" velocity="${scale_value * 0.739146938219599}" />
	</joint>

	<link name="link_6">
		<visual>
			<origin rpy="0 0 0" xyz="0 0 0"/>
			<geometry>
				<mesh filename="package://denso_cobotta_description/meshes/visual/robot/link_6.dae" scale="${scale_value} ${scale_value} ${scale_value}"/>
			</geometry>
		</visual>
		<collision>
			<origin rpy="0 0 0" xyz="0 0 0"/>
			<geometry>
				<mesh filename="package://denso_cobotta_description/meshes/collision/robot/link_6.dae" scale="${scale_value} ${scale_value} ${scale_value}"/>
			</geometry>
		</collision>
	</link>

	<joint name="joint_6" type="revolute">
		<parent link="link_5"/>
		<child link="link_6"/>
		<origin rpy="0.000000 0.000000 0.000000" xyz="0.000000 ${scale_value * (-0.044500)} ${scale_value * 0.042000}" />
		<axis xyz="-0.000000 -0.000000 1.000000" />
		<limit effort="${scale_value * 10000}" lower="-2.96706" upper="2.96706" velocity="${scale_value * 1.109331272567600}" />
	</joint>

	<xacro:if value="${gripper_type != 'none'}">
		<xacro:include filename="$(find denso_cobotta_description)/urdf/${gripper_type}.urdf.xacro" />
	</xacro:if>
</robot>
